os.getcwd /home/soheil/Soheil/lin-python/S/multi
/home/soheil/Soheil/lin-python/S/multi
/home/soheil/Soheil/lin-python/S/multi/
/home/soheil/Soheil/lin-python/S/multi/data/
os.getcwd /home/soheil/Soheil/lin-python/S/multi
/home/soheil/Soheil/lin-python/S/multi/
/home/soheil/Soheil/lin-python/S/multi/
Traceback (most recent call last):
  File "titanic_classifier.py", line 273, in <module>
    fire.Fire()
  File "/home/soheil/.local/lib/python3.8/site-packages/fire/core.py", line 138, in Fire
    component_trace = _Fire(component, args, parsed_flag_args, context, name)
  File "/home/soheil/.local/lib/python3.8/site-packages/fire/core.py", line 463, in _Fire
    component, remaining_args = _CallAndUpdateTrace(
  File "/home/soheil/.local/lib/python3.8/site-packages/fire/core.py", line 672, in _CallAndUpdateTrace
    component = fn(*varargs, **kwargs)
  File "titanic_classifier.py", line 238, in predict
    run_inference2.run_predict(model_class,
TypeError: run_predict() got an unexpected keyword argument 'cols_group'
